<mujoco model="door_main">
    <compiler angle="radian" autolimits="true"/>
    <size/>
    <default/>
    <worldbody>
        <body name="door_main_footprint" pos="1.30 -0.210 0.75" quat="0.707388 0 0 -0.706825">
            <body name="door_container">
                <geom size="0.2 0.025 0.14" pos="-0.2 0.018 0.14" quat="0.707388 0 0 0.706825" type="box" rgba="0.23 0.08 0.08 1"/>
                <geom size="0.2 0.025 0.14" pos="0.2 0.025 0.14" quat="0.707105 0 0 -0.707108" type="box" rgba="0.23 0.08 0.08 1"/>
                <geom size="0.2 0.025 0.14" pos="-0.0069 0.1984 0.14" quat="1.32679e-06 0 0 1" type="box" rgba="0.23 0.08 0.08 1"/>
                <geom size="0.225 0.025 0.2" pos="-0.00029 0.02489 0.3" quat="0.707388 0.706825 0 0" type="box" rgba="0.23 0.08 0.08 1"/>
            </body>
            <body name="door_hinge_body" pos="-0.1675 -0.15548 0.14469" quat="1 0 0 0">
                <inertial pos="0 0 0" quat="0 0 0 1" mass="1" diaginertia="0.001667 0.001667 0.001667"/>
                <geom size="0.015 0.05" type="cylinder" condim="3" friction="1 1 1" rgba="0 1.0 1.0 1.0"/>
                <joint armature="0.01" axis="0 0 1" damping="1" frictionloss="0.1" limited="true" name="door_hinge" range="-1.57 0" type="hinge"/>
                <body name="door" pos="0.176 0 0">
                    <geom size="0.1643 0.025 0.135" type="box" rgba="1 0.423529 0.0392157 1"/>
                    <body name="door_handle_one" pos="0.10 -0.0372 0" quat="0.500398 0.5 -0.5 0.499602">
                        <geom size="0.015 0.02" type="cylinder" rgba="0 0 1 1"/>
                        <body name="door_handle_two" pos="0 -0.028 0.030" quat="0.707 0.707 0.0 0.0 ">
                            <geom size="0.015 0.045"  type="cylinder" rgba="0 0 1 1"/>
                        </body>
                    </body>
                </body>
            </body>
        </body>
    </worldbody>
    <equality/>
</mujoco>
