<mujoco>
    <!-- <include file="pr2_calibrated_with_ft2_without_virtual_joints.xml"/> -->
    <visual>
        <rgba haze="0.15 0.25 0.35 1"/>
        <quality shadowsize="8192"/>
        <global azimuth="220" elevation="-30"/>
    </visual>

    <asset>
        <texture builtin="checker" height="512" name="texplane" rgb1=".2 .3 .4" rgb2=".1 .15 .2" type="2d" width="512" />
        <material name="MatPlane" reflectance="0.05" shininess="0.01" specular="0.01" texrepeat="1 1" texture="texplane" texuniform="true" />
    </asset>

    <worldbody>
        <light pos="0 0 1000" castshadow="false" />
        <geom name="ground_plane" type="plane" size="5 5 10" material="MatPlane" rgba="1 1 1 1"/>
    </worldbody>

    <worldbody>
        <geom name="Table" type="box" pos="0.56428 0.000584 0.2099115" size="0.2265785 0.3210245 0.2099115" rgba=".5 .5 .5 1" />
        <geom name="pick_tray" type="box" pos="0.56428 -0.215704 0.419773" size="0.1175175 0.072463 0.01167" rgba=".0 .0 .5 1" />
        <geom name="place_tray" type="box" pos="0.56428 0.215704 0.419773" size="0.1175175 0.072463 0.01167" rgba=".5 .0 .0 1" />
        <geom name="big_table" type="box" pos="1.40 1.110 0.350" quat="0.707 0 0 0.70710" size="1 0.3210245 0.4099115" rgba="0.788 0.41 0.204 1" />
    </worldbody>

    <worldbody>
        <body name="stone" pos="0.56428 -0.221972 0.475172" >
            <freejoint/>
            <geom name="stone_box" type="box" size=".0125 .016 .032" rgba=".5 .5 .5 1" />
            <inertial pos="0 0 0" mass="0.1024" diaginertia="4.369e-5 4.028e-5 1.407e-5"/>
        </body>
    </worldbody>

    <worldbody>
        <body name="door_main_footprint" pos="1.30 1.08 0.76" quat="0.707388 0 0 -0.706825">
            <body name="door_container">
                <body name="wall1">
                    <inertial pos="0 0 0" quat="0 0 0 1" mass="1.8" diaginertia="0.012135 0.03576 0.024375"/>
                    <geom size="0.2 0.025 0.14" pos="-0.2 0.018 0.14" quat="0.707388 0 0 0.706825" type="box" rgba="0.23 0.08 0.08 1"/>
                </body>
                <body name="wall2">
                    <inertial pos="0 0 0" quat="0 0 0 1" mass="1.8" diaginertia="0.012135 0.03576 0.024375"/>
                    <geom size="0.2 0.025 0.14" pos="0.2 0.025 0.14" quat="0.707105 0 0 -0.707108" type="box" rgba="0.23 0.08 0.08 1"/>
                </body>
                <body name="wall3">
                    <inertial pos="0 0 0" quat="0 0 0 1" mass="1.8" diaginertia="0.012135 0.03576 0.024375"/>
                    <geom size="0.2 0.025 0.14" pos="-0.0069 0.1984 0.14" quat="1.32679e-06 0 0 1" type="box" rgba="0.23 0.08 0.08 1"/>
                </body>
                <body name="wall4">
                    <inertial pos="0 0 0" quat="0 0 0 1" mass="2.0" diaginertia="0.027083 0.0604167 0.034167"/>
                    <geom size="0.225 0.025 0.2" pos="-0.00029 0.02489 0.3" quat="0.707388 0.706825 0 0" type="box" rgba="0.23 0.08 0.08 1"/>
                </body>
            </body>
            <body name="door_main_area" pos="0 0 0.135" quat="0.707 0 0 -0.707">
                <body name="door_hinge" pos="0.1675 -0.15548 0" quat="0.707 0 0 0.707">
                    <inertial pos="0 0 0" quat="0 0 0 1" mass="0.25" diaginertia="0.000222 0.000222 0.000028"/>
                    <geom size="0.015 0.05" type="cylinder" condim="3" friction="1 1 1" rgba="0 1.0 1.0 1.0"/>
                    <joint armature="0.01" axis="0 0 1" damping="1" frictionloss="0.1" limited="true" name="door_hinge_joint" range="-1.57 0" type="hinge"/>
                    <body name="door" pos="0.164 0.010 0" quat="1 0 0 0">
                        <inertial pos="0 0 0" quat="0 0 0 1" mass="1.6" diaginertia="0.010053 0.024117 0.01473"/>
                        <geom name="door_obj" size="0.1643 0.025 0.135" type="box" rgba="1 0.423529 0.0392157 1"/>
                        <body name="door_handle_one" pos="0.140 -0.040 0" quat="0.707 -0.707 0 0">
                            <inertial pos="0 0 0" quat="0 0 0 1" mass="0.125" diaginertia="0.00002369 0.00002369 0.00001406"/>
                            <geom size="0.015 0.02" type="cylinder" rgba="0 0 1 1"/>
                            <body name="door_handle_two" pos="-0.040 0.0 -0.030" quat="0.707 0.0 0.707 0.0 ">
                                <inertial pos="0 0 0" quat="0 0 0 1" mass="0.250" diaginertia="0.0001828125 0.0001828125 0.00002812"/>
                                <geom name="door_handle_two_obj" size="0.015 0.06"  type="cylinder" rgba="0 0 1 1" condim="6" priority="1"/>
                            </body>
                        </body>
                    </body>
                </body>
            </body>
        </body>
    </worldbody> 


</mujoco>