<?xml version="1.0" ?>
<!-- =================================================================================== -->
<!-- |    This document was autogenerated by xacro from iai_kitchen_python.urdf.xacro  | -->
<!-- |    EDITING THIS FILE BY HAND IS NOT RECOMMENDED                                 | -->
<!-- =================================================================================== -->
<robot name="iai_dishwasher">
 
   <link name="odom_combined">
    <inertial>
      <origin rpy="0 0 0" xyz="0.0 0.0 0.0"/>
      <mass value="1"/>
      <inertia ixx="1" ixy="0.0" ixz="0.0" iyy="1" iyz="0.0" izz="1"/>
    </inertial>
  </link>
  <link name="world"/>
  <joint name="world_odom_joint" type="fixed">
    <origin rpy="0 0 0" xyz="0.0 0.0 0 "/>
    <parent link="world"/>
    <child link="odom_combined"/>
  </joint>

  <link name="sink_area_dish_washer_main" />
  
  <link name="dish_top">
    <inertial>
      <origin rpy="0 0 0" xyz="0.0 0.0 0.0"/>
      <mass value="1"/>
      <inertia ixx="1" ixy="0.0" ixz="0.0" iyy="1" iyz="0.0" izz="1"/>
    </inertial>
    <visual>
      <origin rpy="0 0 0" xyz="0 0 0"/>
      <geometry>
        <box size=".620 .54 .062"/>
      </geometry>
    </visual>
    <collision>
      <origin rpy="0 0 0" xyz="0 0 0"/>
      <geometry>
        <box size=".620 .54 .062"/>
      </geometry>
    </collision>
  </link>

  <link name="dish_bottom">
    <inertial>
      <origin rpy="0 0 0" xyz="0.0 0.0 0.0"/>
      <mass value="1"/>
      <inertia ixx="1" ixy="0.0" ixz="0.0" iyy="1" iyz="0.0" izz="1"/>
    </inertial>
    <visual>
    <origin rpy="0 0 0" xyz="0 0 0"/>
      <geometry>
        <box size=".620 .534 .055"/>
      </geometry>
    </visual>
    <collision>
    <origin rpy="0 0 0" xyz="0 0 0"/>
      <geometry>
        <box size=".620 .534 .055"/>
      </geometry>
    </collision>
  </link>

  <link name="dish_back">
    <inertial>
      <origin rpy="0 0 0" xyz="0.0 0.0 0.0"/>
      <mass value="1"/>
      <inertia ixx="1" ixy="0.0" ixz="0.0" iyy="1" iyz="0.0" izz="1"/>
    </inertial>
    <visual>
    <origin rpy="0 0 0" xyz="0 0 0"/>
      <geometry>
        <box size=".0710 .534 0.756"/>
      </geometry>
    </visual>
    <collision>
    <origin rpy="0 0 0" xyz="0 0 0"/>
      <geometry>
        <box size=".0710 .534 0.756"/>
      </geometry>
    </collision>
  </link>

    <link name="dish_right">
      <inertial>
        <origin rpy="0 0 0" xyz="0.0 0.0 0.0"/>
        <mass value="1"/>
        <inertia ixx="1" ixy="0.0" ixz="0.0" iyy="1" iyz="0.0" izz="1"/>
      </inertial>
        <visual>
        <origin rpy="0 0 0" xyz="0 0 0"/>
            <geometry>
                <box size=".620 .062 0.756"/>
            </geometry>
        </visual>
        <collision>
        <origin rpy="0 0 0" xyz="0 0 0"/>
            <geometry>
                <box size=".620 .062 0.756"/>
            </geometry>
        </collision>
    </link>

    <link name="dish_left">
      <inertial>
        <origin rpy="0 0 0" xyz="0.0 0.0 0.0"/>
        <mass value="1"/>
        <inertia ixx="1" ixy="0.0" ixz="0.0" iyy="1" iyz="0.0" izz="1"/>
      </inertial>
        <visual>
        <origin rpy="0 0 0" xyz="0 0 0"/>
            <geometry>
                <box size=".620 .062 0.756"/>
            </geometry>
        </visual>
        <collision>
        <origin rpy="0 0 0" xyz="0 0 0"/>
            <geometry>
                <box size=".620 .062 0.756"/>
            </geometry>
        </collision>
    </link>


   <link name="sink_area_dish_washer_door">
    <inertial>
      <origin rpy="0 0 0" xyz="0.0 0.0 0.0"/>
      <mass value="1"/>
      <inertia ixx="1" ixy="0.0" ixz="0.0" iyy="1" iyz="0.0" izz="1"/>
    </inertial>
    <visual>
      <origin rpy="0 0 0" xyz="0.013 -0.37 0.013"/>
      <geometry>
        <box size=".0420 .73 .540"/>
      </geometry>
    </visual>
    <collision>
      <origin rpy="0 0 0" xyz="0.013 -0.37 0.013"/>
      <geometry>
        <box size=".0420 .73 .540"/>
      </geometry>
    </collision>
  </link>

  <link name="sink_area_dish_washer_door_handle">
    <inertial>
      <origin rpy="0 0 0" xyz="0.0 0.0 0.0"/>
      <mass value="1"/>
      <inertia ixx="1" ixy="0.0" ixz="0.0" iyy="1" iyz="0.0" izz="1"/>
    </inertial>
    <visual>
      <origin rpy="1.57079 0 0" xyz="0 0 0"/>
      <geometry>
        <cylinder length="0.46" radius="0.015" />
      </geometry>
    </visual>
    <collision>
      <origin rpy="1.57079 0 0" xyz="0 0 0"/>
      <geometry>
        <cylinder length="0.46" radius="0.015" />
        <!-- <mesh filename="package://mujoco_sim/model/partial_kitchen/assets/handle60_rot.stl"/> -->
      </geometry>
    </collision>
  </link>


    <joint name="sink_area_dish_washer_main_joint" type="fixed">
        <origin rpy="0 0 3.14" xyz="1.555 0.2 0.4"/>
        <parent link="odom_combined"/>
        <child link="sink_area_dish_washer_main"/>
    </joint>

    <joint name="dish_top_joint" type="fixed">
        <origin rpy="0 0 0" xyz="-0.003 0.011 .352"/>
        <parent link="sink_area_dish_washer_main"/>
        <child link="dish_top"/>
    </joint>

    <joint name="dish_bottom_joint" type="fixed">
        <origin rpy="0 0 0" xyz="-0.003 0.009 -.37"/>
        <parent link="sink_area_dish_washer_main"/>
        <child link="dish_bottom"/>
    </joint>

     <joint name="dish_back_joint" type="fixed">
        <origin rpy="0 0 0" xyz="-0.24 0.01 -0.038"/>
        <parent link="sink_area_dish_washer_main"/>
        <child link="dish_back"/>
    </joint>

     <joint name="dish_right_joint" type="fixed">
        <origin rpy="0 0 0" xyz="-0.004 -.226 -0.01"/>
        <parent link="sink_area_dish_washer_main"/>
        <child link="dish_right"/>
    </joint>

    <joint name="dish_left_joint" type="fixed">
        <origin rpy="0 0 0" xyz="-0.004 0.25 -0.04"/>
        <parent link="sink_area_dish_washer_main"/>
        <child link="dish_left"/>
    </joint>

    <joint name="sink_area_dish_washer_door_joint" type="revolute">
        <origin rpy="-1.5707963267948966 0 0" xyz="0.312 0 -0.35"/>
        <parent link="sink_area_dish_washer_main"/>
        <child link="sink_area_dish_washer_door"/>
        <axis xyz="0 0 1"/>
        <limit effort="300" lower="0" upper="1.5707963267948966" velocity="10"/>
    </joint>

    <joint name="sink_area_dish_washer_door_handle_joint" type="fixed">
        <origin rpy="-1.5707963267948966 0 0" xyz="0.085 -0.580 0.010"/>
        <parent link="sink_area_dish_washer_door"/>
        <child link="sink_area_dish_washer_door_handle"/>
  </joint>
</robot>

