<?xml version="1.0" ?>
<!-- =================================================================================== -->
<!-- |    This document was autogenerated by xacro from iai_kitchen_python.urdf.xacro  | -->
<!-- |    EDITING THIS FILE BY HAND IS NOT RECOMMENDED                                 | -->
<!-- =================================================================================== -->
<robot name="iai_dishwasher">
  <!--- FIXME THIS should NOT be here -->
  <!--
      <link name="map">
      
      <sphere_inertia radius="0" mass="0"/>
      </link>
      <iai_drawer_60_14 name="drawer_1" parent="map">
      <origin rpy="0 0 0" xyz="0 0 1"/>
      </iai_drawer_60_14>
      
      <iai_drawer_80_14 name="drawer_2" parent="map">
      <origin rpy="0 0 0" xyz="0 0 2"/>
      </iai_drawer_80_14>
      
      <iai_drawer_60_29 name="drawer_3" parent="map">
      <origin rpy="0 0 0" xyz="0 0 3"/>
      </iai_drawer_60_29>
      
      <iai_drawer_80_29 name="drawer_4" parent="map">
      <origin rpy="0 0 0" xyz="0 0 4"/>
      </iai_drawer_80_29>
      
      <iai_drawer_100_29 name="drawer_5" parent="map">
      <origin rpy="0 0 0" xyz="0 0 5"/>
      </iai_drawer_100_29>
  -->
   <link name="odom_combined">
    <inertial>
      <origin rpy="0 0 0" xyz="0.0 0.0 0.0"/>
      <mass value="1"/>
      <inertia ixx="1" ixy="0.0" ixz="0.0" iyy="1" iyz="0.0" izz="1"/>
    </inertial>
  </link>
  <link name="world"/>
  <joint name="world_room_joint" type="fixed">
    <origin rpy="0 0 0" xyz="0.0 0.0 0 "/>
    <parent link="world"/>
    <child link="odom_combined"/>
  </joint>
  <link name="sink_area_bottom">
    <visual>
      <geometry>
        <box size="0.59 2.14 0.076"/>
      </geometry>
    </visual>
    <collision>
      <geometry>
        <box size="0.59 2.14 0.076"/>
      </geometry>
    </collision>
  </link>

  <link name="sink_area_top">
    <visual>
      <geometry>
        <box size="0.59 2.14 0.04"/>
      </geometry>
    </visual>
    <collision>
      <geometry>
        <box size="0.59 2.14 0.04"/>
      </geometry>
    </collision>
  </link>

  <link name="sink_area_right">
    <visual>
      <geometry>
        <box size="0.59 0.04 0.898"/>
      </geometry>
    </visual>
    <collision>
      <geometry>
        <box size="0.59 0.04 0.898"/>
      </geometry>
    </collision>
  </link>
  <link name="sink_area_left">
    <visual>
      <geometry>
        <box size="0.59 0.04 0.86"/>
      </geometry>
    </visual>
    <collision>
      <geometry>
        <box size="0.59 0.04 0.86"/>
      </geometry>
    </collision>
  </link>



  <link name="sink_area_dish_washer_main">
    <inertial>
      <origin rpy="0 0 0" xyz="0.0 0.0 0.0"/>
      <mass value="1"/>
      <inertia ixx="1" ixy="0.0" ixz="0.0" iyy="1" iyz="0.0" izz="1"/>
    </inertial>
    <visual>
      <origin rpy="0 0 0" xyz="0 0 0"/>
      <geometry>
        <mesh filename="package://mujoco_sim/model/partial_kitchen/assets/DishWasher.dae"/>
      </geometry>
    </visual>
    <collision>
      <origin rpy="1.57079 0 0" xyz="0 0 0"/>
      <geometry>
        <mesh filename="package://mujoco_sim/model/partial_kitchen/assets/dishwasher.stl"/>
      </geometry>
    </collision>
  </link>
   <link name="sink_area_dish_washer_door">
    <inertial>
      <origin rpy="0 0 0" xyz="0.0 0.0 0.0"/>
      <mass value="1"/>
      <inertia ixx="1" ixy="0.0" ixz="0.0" iyy="1" iyz="0.0" izz="1"/>
    </inertial>
    <visual>
      <origin rpy="1.5707963267948966 0 0" xyz="0 0 0"/>
      <geometry>
        <mesh filename="package://mujoco_sim/model/partial_kitchen/assets/DishWasherDoor.dae"/>
      </geometry>
    </visual>
    <collision>
      <origin rpy="0 0 0" xyz="0 -0.31 0.0"/>
      <geometry>
        <box size="0.02 0.67 0.51"/>
        <!-- <mesh filename="package://mujoco_sim/model/partial_kitchen/assets/dishwasher_door.stl"/> -->
      </geometry>
    </collision>
  </link>
  <link name="sink_area_dish_washer_door_handle">
    <inertial>
      <origin rpy="0 0 0" xyz="0.0 0.0 0.0"/>
      <mass value="1"/>
      <inertia ixx="1" ixy="0.0" ixz="0.0" iyy="1" iyz="0.0" izz="1"/>
    </inertial>
    <visual>
      <origin rpy="0 0 0" xyz="0 0 0"/>
      <geometry>
        <mesh filename="package://iai_kitchen/meshes/handles/Handle60.dae"/>
      </geometry>
    </visual>
    <collision>
      <origin rpy="0 0 0" xyz="0 0 0"/>
      <geometry>
        <mesh filename="package://mujoco_sim/model/partial_kitchen/assets/handle60_rot.stl"/>
      </geometry>
    </collision>
  </link>
    
    <joint name="sink_area_bottom_joint" type="fixed">
        <origin rpy="0 0 -3.14" xyz="1.565 0.3 0.045"/>
        <parent link="odom_combined"/>
        <child link="sink_area_bottom"/>
    </joint>

    <joint name="sink_area_top_joint" type="fixed">
        <origin rpy="0 0 -3.14" xyz="1.565 0.3 0.8"/>
        <parent link="odom_combined"/>
        <child link="sink_area_top"/>
    </joint>

    <joint name="sink_area_right_joint" type="fixed">
        <origin rpy="0 0 -3.14" xyz="1.565 -0.782 0.37"/>
        <parent link="odom_combined"/>
        <child link="sink_area_right"/>
   </joint>

    <joint name="sink_area_left_joint" type="fixed">
        <origin rpy="0 0 -3.14" xyz="1.565 1.35 0.35"/>
        <parent link="odom_combined"/>
        <child link="sink_area_left"/>
   </joint>


    <joint name="sink_area_dish_washer_main_joint" type="fixed">
        <origin rpy="0 0 -3.1415" xyz="1.555 0.2 0.42"/>
        <parent link="odom_combined"/>
        <child link="sink_area_dish_washer_main"/>
    </joint>

    <joint name="sink_area_dish_washer_door_joint" type="revolute">
        <origin rpy="-1.5707963267948966 0 0" xyz="0.28 0 -0.305"/>
        <parent link="sink_area_dish_washer_main"/>
        <child link="sink_area_dish_washer_door"/>
        <axis xyz="0 0 1"/>
        <!--
        <limit lower="0" upper="${0.5*pi}" effort="300" velocity="10"/>
        -->
        <limit effort="300" lower="0" upper="1.5707963267948966" velocity="10"/>
    </joint>

    <joint name="sink_area_dish_washer_door_handle_joint" type="fixed">
        <origin rpy="-1.5707963267948966 0 0" xyz="0.073 -0.58 0"/>
        <parent link="sink_area_dish_washer_door"/>
        <child link="sink_area_dish_washer_door_handle"/>
  </joint>
</robot>

